Workbook

Sheet Assumptions
A1: GEOTHERMAL POWER PROJECT — ASSUMPTIONS
A2: All hardcoded inputs are BLUE. Black = formula. Green = link from another sheet. Change any blue cell to run a new scenario.
A3: Units: US$ million unless stated. Tariff/OPEX in US$ per kWh / MWh as labelled.
A4: 1. DATES & TIMELINE
A5: Construction Start Date | B5: 46388
A6: Construction Period (years) | B6: 3
A7: Commercial Operation Date (COD) | B7: =EDATE(B5,B6*12) -> 47484
A8: Operating Life (years) | B8: 30
A9: PPA Tenor (years) | B9: 30
A10: Operating Life End Date | B10: =EDATE(B7,B8*12) -> 58441
A12: 2. PROJECT / TECHNICAL ASSUMPTIONS
A13: Installed Capacity (MW) | B13: 55
A14: Capacity Factor (%) | B14: 0.9
A15: Annual Generation (GWh) | B15: =B13*B14*8760/1000 -> 433.62 | C15: GWh p.a.
A17: 3. CAPEX ASSUMPTIONS
A18: CAPEX per MW (US$m/MW) | B18: 4.5
A19: Total CAPEX (US$m) | B19: =B13*B18 -> 247.5
A20: Development Costs (US$m) | B20: 8
A21: Financing Fee (% of Debt) | B21: 0.015
A22: CAPEX Phasing (% of Total CAPEX by construction year)
A23: Construction Year 1 | B23: 0.3
A24: Construction Year 2 | B24: 0.45
A25: Construction Year 3 | B25: 0.25
A26: Construction Year 4 | B26: 0
A27: Construction Year 5 | B27: 0
A28: Phasing Check (must = 100%) | B28: =SUM(B23:B27) -> 1
A30: 4. VAT & IMPORT DUTY
A31: VAT Rate (%) | B31: 0.11
A32: Import Duty Rate (%) | B32: 0.05
A33: % of CAPEX Subject to Import Duty | B33: 0.6
A35: 5. CORPORATE TAX
A36: Corporate Income Tax Rate (%) | B36: 0.22
A37: Tax Holiday Period (years from COD) | B37: 5
A38: Tax Allowance (% of CAPEX) | B38: 0.3
A39: Tax Allowance Period (years, straight-line) | B39: 6
A40: Tax Depreciation Life (years, SL) | B40: 20
A41: Accounting Depreciation Life (years, SL) | B41: 30
A42: Tax Loss Carryforward Limit (years) | B42: 99
A43: Tax Incentive Scenario | B43: Holiday + Allowance
A45: 6. TARIFF & REVENUE
...

Sheet CAPEX_SU
A1: CAPEX & SOURCES AND USES OF FUNDS
A2: CAPEX phased over the construction period; VAT and import duty are real, non-recoverable cash costs added to total project cost.
A4: Calendar Year | D4: =Assumptions!D66 -> 2027 | E4: =Assumptions!E66 -> 2028 | F4: =Assumptions!F66 -> 2029 | G4: =Assumptions!G66 -> 2030 | H4: =Assumptions!H66 -> 2031 | I4: =Assumptions!I66 -> 2032 | J4: =Assumptions!J66 -> 2033 | K4: =Assumptions!K66 -> 2034 | ... AQ4: =Assumptions!AQ66 -> 2066
A5: Period | D5: =Assumptions!D67 -> Construction | E5: =Assumptions!E67 -> Construction | F5: =Assumptions!F67 -> Construction | G5: =Assumptions!G67 -> Operation | H5: =Assumptions!H67 -> Operation | I5: =Assumptions!I67 -> Operation | J5: =Assumptions!J67 -> Operation | K5: =Assumptions!K67 -> Operation | ... AQ5: =Assumptions!AQ67 -> -
A6: Operating Year # | D6: =Assumptions!D69 | E6: =Assumptions!E69 | F6: =Assumptions!F69 | G6: =Assumptions!G69 -> 1 | H6: =Assumptions!H69 -> 2 | I6: =Assumptions!I69 -> 3 | J6: =Assumptions!J69 -> 4 | K6: =Assumptions!K69 -> 5 | ... AQ6: =Assumptions!AQ69
A7: Construction Year # | D7: =Assumptions!D68 -> 1 | E7: =Assumptions!E68 -> 2 | F7: =Assumptions!F68 -> 3 | G7: =Assumptions!G68 | H7: =Assumptions!H68 | I7: =Assumptions!I68 | J7: =Assumptions!J68 | K7: =Assumptions!K68 | ... AQ7: =Assumptions!AQ68
A8: USES OF FUNDS (US$ million)
A9: CAPEX Phasing (%) | D9: =IF(D7<>"",INDEX(Assumptions!$B$23:$B$27,D7),0) -> 0.3 | E9: =IF(E7<>"",INDEX(Assumptions!$B$23:$B$27,E7),0) -> 0.45 | F9: =IF(F7<>"",INDEX(Assumptions!$B$23:$B$27,F7),0) -> 0.25 | G9: =IF(G7<>"",INDEX(Assumptions!$B$23:$B$27,G7),0) -> 0 | H9: =IF(H7<>"",INDEX(Assumptions!$B$23:$B$27,H7),0) -> 0 | I9: =IF(I7<>"",INDEX(Assumptions!$B$23:$B$27,I7),0) -> 0 | J9: =IF(J7<>"",INDEX(Assumptions!$B$23:$B$27,J7),0) -> 0 | K9: =IF(K7<>"",INDEX(Assumptions!$B$23:$B$27,K7),0) -> 0 | ... AQ9: =IF(AQ7<>"",INDEX(Assumptions!$B$23:$B$27,AQ7),0) -> 0
A10: CAPEX | D10: =Assumptions!$B$19*D9 -> 74.25 | E10: =Assumptions!$B$19*E9 -> 111.375 | F10: =Assumptions!$B$19*F9 -> 61.875 | G10: =Assumptions!$B$19*G9 -> 0 | H10: =Assumptions!$B$19*H9 -> 0 | I10: =Assumptions!$B$19*I9 -> 0 | J10: =Assumptions!$B$19*J9 -> 0 | K10: =Assumptions!$B$19*K9 -> 0 | ... AQ10: =Assumptions!$B$19*AQ9 -> 0
A11: Import Duty | D11: =D10*Assumptions!$B$33*Assumptions!$B$32 -> 2.2275 | E11: =E10*Assumptions!$B$33*Assumptions!$B$32 -> 3.34125 | F11: =F10*Assumptions!$B$33*Assumptions!$B$32 -> 1.85625 | G11: =G10*Assumptions!$B$33*Assumptions!$B$32 -> 0 | H11: =H10*Assumptions!$B$33*Assumptions!$B$32 -> 0 | I11: =I10*Assumptions!$B$33*Assumptions!$B$32 -> 0 | J11: =J10*Assumptions!$B$33*Assumptions!$B$32 -> 0 | K11: =K10*Assumptions!$B$33*Assumptions!$B$32 -> 0 | ... AQ11: =AQ10*Assumptions!$B$33*Assumptions!$B$32 -> 0
A12: VAT (on CAPEX + Duty) | D12: =(D10+D11)*Assumptions!$B$31 -> 8.412525 | E12: =(E10+E11)*Assumptions!$B$31 -> 12.618787 | F12: =(F10+F11)*Assumptions!$B$31 -> 7.0104375 | G12: =(G10+G11)*Assumptions!$B$31 -> 0 | H12: =(H10+H11)*Assumptions!$B$31 -> 0 | I12: =(I10+I11)*Assumptions!$B$31 -> 0 | J12: =(J10+J11)*Assumptions!$B$31 -> 0 | K12: =(K10+K11)*Assumptions!$B$31 -> 0 | ... AQ12: =(AQ10+AQ11)*Assumptions!$B$31 -> 0
A13: Development Costs | D13: =IF(D7=1,Assumptions!$B$20,0) -> 8 | E13: =IF(E7=1,Assumptions!$B$20,0) -> 0 | F13: =IF(F7=1,Assumptions!$B$20,0) -> 0 | G13: =IF(G7=1,Assumptions!$B$20,0) -> 0 | H13: =IF(H7=1,Assumptions!$B$20,0) -> 0 | I13: =IF(I7=1,Assumptions!$B$20,0) -> 0 | J13: =IF(J7=1,Assumptions!$B$20,0) -> 0 | K13: =IF(K7=1,Assumptions!$B$20,0) -> 0 | ... AQ13: =IF(AQ7=1,Assumptions!$B$20,0) -> 0
A14: Financing Fee (on Loan Amount) | D14: =IF(D7=Assumptions!$B$6,Assumptions!$B$21*Debt!$C$19,0) -> 0 | E14: =IF(E7=Assumptions!$B$6,Assumptions!$B$21*Debt!$C$19,0) -> 0 | F14: =IF(F7=Assumptions!$B$6,Assumptions!$B$21*Debt!$C$19,0) -> 2.2761138 | G14: =IF(G7=Assumptions!$B$6,Assumptions!$B$21*Debt!$C$19,0) -> 0 | H14: =IF(H7=Assumptions!$B$6,Assumptions!$B$21*Debt!$C$19,0) -> 0 | I14: =IF(I7=Assumptions!$B$6,Assumptions!$B$21*Debt!$C$19,0) -> 0 | J14: =IF(J7=Assumptions!$B$6,Assumptions!$B$21*Debt!$C$19,0) -> 0 | K14: =IF(K7=Assumptions!$B$6,Assumptions!$B$21*Debt!$C$19,0) -> 0 | ... AQ14: =IF(AQ7=Assumptions!$B$6,Assumptions!$B$21*Debt!$C$19,0) -> 0
A15: Total Uses of Funds | D15: =SUM(D10:D14) -> 92.890025 | E15: =SUM(E10:E14) -> 127.33504 | F15: =SUM(F10:F14) -> 73.017801 | G15: =SUM(G10:G14) -> 0 | H15: =SUM(H10:H14) -> 0 | I15: =SUM(I10:I14) -> 0 | J15: =SUM(J10:J14) -> 0 | K15: =SUM(K10:K14) -> 0 | ... AQ15: =SUM(AQ10:AQ14) -> 0
A17: SOURCES OF FUNDS (US$ million) — Debt % applied pro-rata to construction-period spend; Debt amount itself is sized on the Debt tab from operating CFADS
A18: Debt Drawdown | D18: =D15*$C$32 -> 48.066704 | E18: =E15*$C$32 -> 65.890558 | F18: =F15*$C$32 -> 37.783659 | G18: =G15*$C$32 -> 0 | H18: =H15*$C$32 -> 0 | I18: =I15*$C$32 -> 0 | J18: =J15*$C$32 -> 0 | K18: =K15*$C$32 -> 0 | ... AQ18: =AQ15*$C$32 -> 0
A19: Equity Contribution | D19: =D15-D18 -> 44.823321 | E19: =E15-E18 -> 61.444479 | F19: =F15-F18 -> 35.234142 | G19: =G15-G18 -> 0 | H19: =H15-H18 -> 0 | I19: =I15-I18 -> 0 | J19: =J15-J18 -> 0 | K19: =K15-K18 -> 0 | ... AQ19: =AQ15-AQ18 -> 0
A20: Total Sources of Funds | D20: =D18+D19 -> 92.890025 | E20: =E18+E19 -> 127.33504 | F20: =F18+F19 -> 73.017801 | G20: =G18+G19 -> 0 | H20: =H18+H19 -> 0 | I20: =I18+I19 -> 0 | J20: =J18+J19 -> 0 | K20: =K18+K19 -> 0 | ... AQ20: =AQ18+AQ19 -> 0
A21: Check: Sources − Uses (= 0) | D21: =D20-D15 -> 0 | E21: =E20-E15 -> 0 | F21: =F20-F15 -> 0 | G21: =G20-G15 -> 0 | H21: =H20-H15 -> 0 | I21: =I20-I15 -> 0 | J21: =J20-J15 -> 0 | K21: =K20-K15 -> 0 | ... AQ21: =AQ20-AQ15 -> 0
A23: SUMMARY (US$ million)
A24: Total CAPEX | C24: =SUM(D10:AQ10) -> 247.5
A25: Total Import Duty | C25: =SUM(D11:AQ11) -> 7.425
A26: Total VAT | C26: =SUM(D12:AQ12) -> 28.04175
A27: Total Development Costs | C27: =SUM(D13:AQ13) -> 8
A28: Total Financing Fee | C28: =SUM(D14:AQ14) -> 2.2761138
A29: Total Project Cost (Total Uses) | C29: =SUM(D15:AQ15) -> 293.24286
A31: Maximum Debt Capacity (Loan Amount) | C31: =Debt!$C$19 -> 151.74092
A32: Debt % of Total Funding | C32: =C31/C29 -> 0.51745819
A33: Equity Requirement | C33: =C29-C31 -> 141.50194
A34: Equity % of Total Funding | C34: =C33/C29 -> 0.48254181

Sheet Revenue_OPEX
A1: TARIFF, REVENUE & OPERATING COSTS
A2: Revenue = Generation (GWh) x Tariff (US$/kWh), which is already in US$ million (1 GWh x US$1/kWh = US$1m). Gated to the PPA tenor.
A4: Calendar Year | D4: =Assumptions!D66 -> 2027 | E4: =Assumptions!E66 -> 2028 | F4: =Assumptions!F66 -> 2029 | G4: =Assumptions!G66 -> 2030 | H4: =Assumptions!H66 -> 2031 | I4: =Assumptions!I66 -> 2032 | J4: =Assumptions!J66 -> 2033 | K4: =Assumptions!K66 -> 2034 | ... AQ4: =Assumptions!AQ66 -> 2066
A5: Period | D5: =Assumptions!D67 -> Construction | E5: =Assumptions!E67 -> Construction | F5: =Assumptions!F67 -> Construction | G5: =Assumptions!G67 -> Operation | H5: =Assumptions!H67 -> Operation | I5: =Assumptions!I67 -> Operation | J5: =Assumptions!J67 -> Operation | K5: =Assumptions!K67 -> Operation | ... AQ5: =Assumptions!AQ67 -> -
A6: Operating Year # | D6: =Assumptions!D69 | E6: =Assumptions!E69 | F6: =Assumptions!F69 | G6: =Assumptions!G69 -> 1 | H6: =Assumptions!H69 -> 2 | I6: =Assumptions!I69 -> 3 | J6: =Assumptions!J69 -> 4 | K6: =Assumptions!K69 -> 5 | ... AQ6: =Assumptions!AQ69
A8: GENERATION & REVENUE
A9: Generation (GWh) | D9: =IF(D6<>"",Assumptions!$B$15,0) -> 0 | E9: =IF(E6<>"",Assumptions!$B$15,0) -> 0 | F9: =IF(F6<>"",Assumptions!$B$15,0) -> 0 | G9: =IF(G6<>"",Assumptions!$B$15,0) -> 433.62 | H9: =IF(H6<>"",Assumptions!$B$15,0) -> 433.62 | I9: =IF(I6<>"",Assumptions!$B$15,0) -> 433.62 | J9: =IF(J6<>"",Assumptions!$B$15,0) -> 433.62 | K9: =IF(K6<>"",Assumptions!$B$15,0) -> 433.62 | ... AQ9: =IF(AQ6<>"",Assumptions!$B$15,0) -> 0
A10: Within PPA Tenor (1/0) | D10: =Assumptions!D71 -> 0 | E10: =Assumptions!E71 -> 0 | F10: =Assumptions!F71 -> 0 | G10: =Assumptions!G71 -> 1 | H10: =Assumptions!H71 -> 1 | I10: =Assumptions!I71 -> 1 | J10: =Assumptions!J71 -> 1 | K10: =Assumptions!K71 -> 1 | ... AQ10: =Assumptions!AQ71 -> 0
A11: Tariff (US$/kWh) | D11: =IF(D6="",0,IF(Assumptions!$B$48="Escalated",Assumptions!$B$46*(1+Assumptions!$B$47)^MAX(D6-Assumptions!$B$49,0),Assumptions!$B$46)) -> 0 | E11: =IF(E6="",0,IF(Assumptions!$B$48="Escalated",Assumptions!$B$46*(1+Assumptions!$B$47)^MAX(E6-Assumptions!$B$49,0),Assumptions!$B$46)) -> 0 | F11: =IF(F6="",0,IF(Assumptions!$B$48="Escalated",Assumptions!$B$46*(1+Assumptions!$B$47)^MAX(F6-Assumptions!$B$49,0),Assumptions!$B$46)) -> 0 | G11: =IF(G6="",0,IF(Assumptions!$B$48="Escalated",Assumptions!$B$46*(1+Assumptions!$B$47)^MAX(G6-Assumptions!$B$49,0),Assumptions!$B$46)) -> 0.06 | H11: =IF(H6="",0,IF(Assumptions!$B$48="Escalated",Assumptions!$B$46*(1+Assumptions!$B$47)^MAX(H6-Assumptions!$B$49,0),Assumptions!$B$46)) -> 0.0612 | I11: =IF(I6="",0,IF(Assumptions!$B$48="Escalated",Assumptions!$B$46*(1+Assumptions!$B$47)^MAX(I6-Assumptions!$B$49,0),Assumptions!$B$46)) -> 0.062424 | J11: =IF(J6="",0,IF(Assumptions!$B$48="Escalated",Assumptions!$B$46*(1+Assumptions!$B$47)^MAX(J6-Assumptions!$B$49,0),Assumptions!$B$46)) -> 0.06367248 | K11: =IF(K6="",0,IF(Assumptions!$B$48="Escalated",Assumptions!$B$46*(1+Assumptions!$B$47)^MAX(K6-Assumptions!$B$49,0),Assumptions!$B$46)) -> 0.06494593 | ... AQ11: =IF(AQ6="",0,IF(Assumptions!$B$48="Escalated",Assumptions!$B$46*(1+Assumptions!$B$47)^MAX(AQ6-Assumptions!$B$49,0),Assumptions!$B$46)) -> 0
A12: Revenue (US$m) | D12: =D9*D11*D10 -> 0 | E12: =E9*E11*E10 -> 0 | F12: =F9*F11*F10 -> 0 | G12: =G9*G11*G10 -> 26.0172 | H12: =H9*H11*H10 -> 26.537544 | I12: =I9*I11*I10 -> 27.068295 | J12: =J9*J11*J10 -> 27.609661 | K12: =K9*K11*K10 -> 28.161854 | ... AQ12: =AQ9*AQ11*AQ10 -> 0
A14: OPERATING COSTS
A15: OPEX — Base (US$m) | D15: =IF(D6="",0,D9*Assumptions!$B$52*(1+Assumptions!$B$54)^MAX(D6-1,0)/1000) -> 0 | E15: =IF(E6="",0,E9*Assumptions!$B$52*(1+Assumptions!$B$54)^MAX(E6-1,0)/1000) -> 0 | F15: =IF(F6="",0,F9*Assumptions!$B$52*(1+Assumptions!$B$54)^MAX(F6-1,0)/1000) -> 0 | G15: =IF(G6="",0,G9*Assumptions!$B$52*(1+Assumptions!$B$54)^MAX(G6-1,0)/1000) -> 6.5043 | H15: =IF(H6="",0,H9*Assumptions!$B$52*(1+Assumptions!$B$54)^MAX(H6-1,0)/1000) -> 6.634386 | I15: =IF(I6="",0,I9*Assumptions!$B$52*(1+Assumptions!$B$54)^MAX(I6-1,0)/1000) -> 6.7670737 | J15: =IF(J6="",0,J9*Assumptions!$B$52*(1+Assumptions!$B$54)^MAX(J6-1,0)/1000) -> 6.9024152 | K15: =IF(K6="",0,K9*Assumptions!$B$52*(1+Assumptions!$B$54)^MAX(K6-1,0)/1000) -> 7.0404635 | ... AQ15: =IF(AQ6="",0,AQ9*Assumptions!$B$52*(1+Assumptions!$B$54)^MAX(AQ6-1,0)/1000) -> 0
A16: OPEX — VAT Cost, non-recoverable (US$m) | D16: =D15*Assumptions!$B$53*Assumptions!$B$31 -> 0 | E16: =E15*Assumptions!$B$53*Assumptions!$B$31 -> 0 | F16: =F15*Assumptions!$B$53*Assumptions!$B$31 -> 0 | G16: =G15*Assumptions!$B$53*Assumptions!$B$31 -> 0.5008311 | H16: =H15*Assumptions!$B$53*Assumptions!$B$31 -> 0.51084772 | I16: =I15*Assumptions!$B$53*Assumptions!$B$31 -> 0.52106468 | J16: =J15*Assumptions!$B$53*Assumptions!$B$31 -> 0.53148597 | K16: =K15*Assumptions!$B$53*Assumptions!$B$31 -> 0.54211569 | ... AQ16: =AQ15*Assumptions!$B$53*Assumptions!$B$31 -> 0
A17: Total Cash OPEX (US$m) | D17: =D15+D16 -> 0 | E17: =E15+E16 -> 0 | F17: =F15+F16 -> 0 | G17: =G15+G16 -> 7.0051311 | H17: =H15+H16 -> 7.1452337 | I17: =I15+I16 -> 7.2881384 | J17: =J15+J16 -> 7.4339012 | K17: =K15+K16 -> 7.5825792 | ... AQ17: =AQ15+AQ16 -> 0
A19: EBITDA (US$m) | D19: =D12-D17 -> 0 | E19: =E12-E17 -> 0 | F19: =F12-F17 -> 0 | G19: =G12-G17 -> 19.012069 | H19: =H12-H17 -> 19.39231 | I19: =I12-I17 -> 19.780156 | J19: =J12-J17 -> 20.17576 | K19: =K12-K17 -> 20.579275 | ... AQ19: =AQ12-AQ17 -> 0

Sheet Tax
A1: CORPORATE TAX — HOLIDAY, ALLOWANCE, DEPRECIATION & LOSS CARRYFORWARD
A2: Tax Incentive Scenario switch (Assumptions!B43) turns the holiday and/or allowance on or off so scenarios can be compared on this tab alone.
A4: Calendar Year | D4: =Assumptions!D66 -> 2027 | E4: =Assumptions!E66 -> 2028 | F4: =Assumptions!F66 -> 2029 | G4: =Assumptions!G66 -> 2030 | H4: =Assumptions!H66 -> 2031 | I4: =Assumptions!I66 -> 2032 | J4: =Assumptions!J66 -> 2033 | K4: =Assumptions!K66 -> 2034 | ... AQ4: =Assumptions!AQ66 -> 2066
A5: Period | D5: =Assumptions!D67 -> Construction | E5: =Assumptions!E67 -> Construction | F5: =Assumptions!F67 -> Construction | G5: =Assumptions!G67 -> Operation | H5: =Assumptions!H67 -> Operation | I5: =Assumptions!I67 -> Operation | J5: =Assumptions!J67 -> Operation | K5: =Assumptions!K67 -> Operation | ... AQ5: =Assumptions!AQ67 -> -
A6: Operating Year # | D6: =Assumptions!D69 | E6: =Assumptions!E69 | F6: =Assumptions!F69 | G6: =Assumptions!G69 -> 1 | H6: =Assumptions!H69 -> 2 | I6: =Assumptions!I69 -> 3 | J6: =Assumptions!J69 -> 4 | K6: =Assumptions!K69 -> 5 | ... AQ6: =Assumptions!AQ69
A8: TAX INCENTIVE FLAGS & DEPRECIATION
A9: Tax Holiday Active (1/0) | D9: =IF(OR(Assumptions!$B$43="Tax Holiday Only",Assumptions!$B$43="Holiday + Allowance"),Assumptions!D72,0) -> 0 | E9: =IF(OR(Assumptions!$B$43="Tax Holiday Only",Assumptions!$B$43="Holiday + Allowance"),Assumptions!E72,0) -> 0 | F9: =IF(OR(Assumptions!$B$43="Tax Holiday Only",Assumptions!$B$43="Holiday + Allowance"),Assumptions!F72,0) -> 0 | G9: =IF(OR(Assumptions!$B$43="Tax Holiday Only",Assumptions!$B$43="Holiday + Allowance"),Assumptions!G72,0) -> 1 | H9: =IF(OR(Assumptions!$B$43="Tax Holiday Only",Assumptions!$B$43="Holiday + Allowance"),Assumptions!H72,0) -> 1 | I9: =IF(OR(Assumptions!$B$43="Tax Holiday Only",Assumptions!$B$43="Holiday + Allowance"),Assumptions!I72,0) -> 1 | J9: =IF(OR(Assumptions!$B$43="Tax Holiday Only",Assumptions!$B$43="Holiday + Allowance"),Assumptions!J72,0) -> 1 | K9: =IF(OR(Assumptions!$B$43="Tax Holiday Only",Assumptions!$B$43="Holiday + Allowance"),Assumptions!K72,0) -> 1 | ... AQ9: =IF(OR(Assumptions!$B$43="Tax Holiday Only",Assumptions!$B$43="Holiday + Allowance"),Assumptions!AQ72,0) -> 0
A10: Tax Allowance Active (1/0) | D10: =IF(OR(Assumptions!$B$43="Tax Allowance Only",Assumptions!$B$43="Holiday + Allowance"),Assumptions!D73,0) -> 0 | E10: =IF(OR(Assumptions!$B$43="Tax Allowance Only",Assumptions!$B$43="Holiday + Allowance"),Assumptions!E73,0) -> 0 | F10: =IF(OR(Assumptions!$B$43="Tax Allowance Only",Assumptions!$B$43="Holiday + Allowance"),Assumptions!F73,0) -> 0 | G10: =IF(OR(Assumptions!$B$43="Tax Allowance Only",Assumptions!$B$43="Holiday + Allowance"),Assumptions!G73,0) -> 1 | H10: =IF(OR(Assumptions!$B$43="Tax Allowance Only",Assumptions!$B$43="Holiday + Allowance"),Assumptions!H73,0) -> 1 | I10: =IF(OR(Assumptions!$B$43="Tax Allowance Only",Assumptions!$B$43="Holiday + Allowance"),Assumptions!I73,0) -> 1 | J10: =IF(OR(Assumptions!$B$43="Tax Allowance Only",Assumptions!$B$43="Holiday + Allowance"),Assumptions!J73,0) -> 1 | K10: =IF(OR(Assumptions!$B$43="Tax Allowance Only",Assumptions!$B$43="Holiday + Allowance"),Assumptions!K73,0) -> 1 | ... AQ10: =IF(OR(Assumptions!$B$43="Tax Allowance Only",Assumptions!$B$43="Holiday + Allowance"),Assumptions!AQ73,0) -> 0
A11: Tax Allowance Deduction (US$m) | D11: =D10*(Assumptions!$B$19*Assumptions!$B$38/Assumptions!$B$39) -> 0 | E11: =E10*(Assumptions!$B$19*Assumptions!$B$38/Assumptions!$B$39) -> 0 | F11: =F10*(Assumptions!$B$19*Assumptions!$B$38/Assumptions!$B$39) -> 0 | G11: =G10*(Assumptions!$B$19*Assumptions!$B$38/Assumptions!$B$39) -> 12.375 | H11: =H10*(Assumptions!$B$19*Assumptions!$B$38/Assumptions!$B$39) -> 12.375 | I11: =I10*(Assumptions!$B$19*Assumptions!$B$38/Assumptions!$B$39) -> 12.375 | J11: =J10*(Assumptions!$B$19*Assumptions!$B$38/Assumptions!$B$39) -> 12.375 | K11: =K10*(Assumptions!$B$19*Assumptions!$B$38/Assumptions!$B$39) -> 12.375 | ... AQ11: =AQ10*(Assumptions!$B$19*Assumptions!$B$38/Assumptions!$B$39) -> 0
A12: Tax Depreciation (US$m, SL) | D12: =IF(AND(D6<>"",D6<=Assumptions!$B$40),Assumptions!$B$19/Assumptions!$B$40,0) -> 0 | E12: =IF(AND(E6<>"",E6<=Assumptions!$B$40),Assumptions!$B$19/Assumptions!$B$40,0) -> 0 | F12: =IF(AND(F6<>"",F6<=Assumptions!$B$40),Assumptions!$B$19/Assumptions!$B$40,0) -> 0 | G12: =IF(AND(G6<>"",G6<=Assumptions!$B$40),Assumptions!$B$19/Assumptions!$B$40,0) -> 12.375 | H12: =IF(AND(H6<>"",H6<=Assumptions!$B$40),Assumptions!$B$19/Assumptions!$B$40,0) -> 12.375 | I12: =IF(AND(I6<>"",I6<=Assumptions!$B$40),Assumptions!$B$19/Assumptions!$B$40,0) -> 12.375 | J12: =IF(AND(J6<>"",J6<=Assumptions!$B$40),Assumptions!$B$19/Assumptions!$B$40,0) -> 12.375 | K12: =IF(AND(K6<>"",K6<=Assumptions!$B$40),Assumptions!$B$19/Assumptions!$B$40,0) -> 12.375 | ... AQ12: =IF(AND(AQ6<>"",AQ6<=Assumptions!$B$40),Assumptions!$B$19/Assumptions!$B$40,0) -> 0
A13: Accounting Depreciation (US$m, SL) | D13: =IF(AND(D6<>"",D6<=Assumptions!$B$41),Assumptions!$B$19/Assumptions!$B$41,0) -> 0 | E13: =IF(AND(E6<>"",E6<=Assumptions!$B$41),Assumptions!$B$19/Assumptions!$B$41,0) -> 0 | F13: =IF(AND(F6<>"",F6<=Assumptions!$B$41),Assumptions!$B$19/Assumptions!$B$41,0) -> 0 | G13: =IF(AND(G6<>"",G6<=Assumptions!$B$41),Assumptions!$B$19/Assumptions!$B$41,0) -> 8.25 | H13: =IF(AND(H6<>"",H6<=Assumptions!$B$41),Assumptions!$B$19/Assumptions!$B$41,0) -> 8.25 | I13: =IF(AND(I6<>"",I6<=Assumptions!$B$41),Assumptions!$B$19/Assumptions!$B$41,0) -> 8.25 | J13: =IF(AND(J6<>"",J6<=Assumptions!$B$41),Assumptions!$B$19/Assumptions!$B$41,0) -> 8.25 | K13: =IF(AND(K6<>"",K6<=Assumptions!$B$41),Assumptions!$B$19/Assumptions!$B$41,0) -> 8.25 | ... AQ13: =IF(AND(AQ6<>"",AQ6<=Assumptions!$B$41),Assumptions!$B$19/Assumptions!$B$41,0) -> 0
A15: LEVERED TAX CALCULATION (drives CFADS & Equity Cash Flow)
A16: EBITDA | D16: =Revenue_OPEX!D19 -> 0 | E16: =Revenue_OPEX!E19 -> 0 | F16: =Revenue_OPEX!F19 -> 0 | G16: =Revenue_OPEX!G19 -> 19.012069 | H16: =Revenue_OPEX!H19 -> 19.39231 | I16: =Revenue_OPEX!I19 -> 19.780156 | J16: =Revenue_OPEX!J19 -> 20.17576 | K16: =Revenue_OPEX!K19 -> 20.579275 | ... AQ16: =Revenue_OPEX!AQ19 -> 0
A17: Interest Expense | D17: =Debt!D23 -> 0 | E17: =Debt!E23 -> 0 | F17: =Debt!F23 -> 0 | G17: =Debt!G23 -> 9.8631599 | H17: =Debt!H23 -> 9.5731748 | I17: =Debt!I23 -> 9.2457188 | J17: =Debt!J23 -> 8.8779839 | K17: =Debt!K23 -> 8.4669721 | ... AQ17: =Debt!AQ23 -> 0
A18: Taxable Income before Loss Carryforward | D18: =D16-D12-D11-D17 -> 0 | E18: =E16-E12-E11-E17 -> 0 | F18: =F16-F12-F11-F17 -> 0 | G18: =G16-G12-G11-G17 -> -15.601091 | H18: =H16-H12-H11-H17 -> -14.930864 | I18: =I16-I12-I11-I17 -> -14.215562 | J18: =J16-J12-J11-J17 -> -13.452224 | K18: =K16-K12-K11-K17 -> -12.637697 | ... AQ18: =AQ16-AQ12-AQ11-AQ17 -> 0
A19: Opening Tax Loss Carryforward | D19: 0 | E19: =D22 -> 0 | F19: =E22 -> 0 | G19: =F22 -> 0 | H19: =G22 -> 15.601091 | I19: =H22 -> 30.531955 | J19: =I22 -> 44.747518 | K19: =J22 -> 58.199742 | L19: =K22 -> 70.837439 | ... AQ19: =AP22 -> 0
A20: Loss Generated | D20: =IF(D18<0,-D18,0) -> 0 | E20: =IF(E18<0,-E18,0) -> 0 | F20: =IF(F18<0,-F18,0) -> 0 | G20: =IF(G18<0,-G18,0) -> 15.601091 | H20: =IF(H18<0,-H18,0) -> 14.930864 | I20: =IF(I18<0,-I18,0) -> 14.215562 | J20: =IF(J18<0,-J18,0) -> 13.452224 | K20: =IF(K18<0,-K18,0) -> 12.637697 | ... AQ20: =IF(AQ18<0,-AQ18,0) -> 0
A21: Loss Utilized | D21: =MIN(D19,MAX(D18,0)) -> 0 | E21: =MIN(E19,MAX(E18,0)) -> 0 | F21: =MIN(F19,MAX(F18,0)) -> 0 | G21: =MIN(G19,MAX(G18,0)) -> 0 | H21: =MIN(H19,MAX(H18,0)) -> 0 | I21: =MIN(I19,MAX(I18,0)) -> 0 | J21: =MIN(J19,MAX(J18,0)) -> 0 | K21: =MIN(K19,MAX(K18,0)) -> 0 | ... AQ21: =MIN(AQ19,MAX(AQ18,0)) -> 0
A22: Closing Tax Loss Carryforward | D22: =D19+D20-D21 -> 0 | E22: =E19+E20-E21 -> 0 | F22: =F19+F20-F21 -> 0 | G22: =G19+G20-G21 -> 15.601091 | H22: =H19+H20-H21 -> 30.531955 | I22: =I19+I20-I21 -> 44.747518 | J22: =J19+J20-J21 -> 58.199742 | K22: =K19+K20-K21 -> 70.837439 | ... AQ22: =AQ19+AQ20-AQ21 -> 0
A23: Taxable Income after Loss Carryforward | D23: =MAX(D18,0)-D21 -> 0 | E23: =MAX(E18,0)-E21 -> 0 | F23: =MAX(F18,0)-F21 -> 0 | G23: =MAX(G18,0)-G21 -> 0 | H23: =MAX(H18,0)-H21 -> 0 | I23: =MAX(I18,0)-I21 -> 0 | J23: =MAX(J18,0)-J21 -> 0 | K23: =MAX(K18,0)-K21 -> 0 | ... AQ23: =MAX(AQ18,0)-AQ21 -> 0
A24: Tax Payable (before Holiday) | D24: =D23*Assumptions!$B$36 -> 0 | E24: =E23*Assumptions!$B$36 -> 0 | F24: =F23*Assumptions!$B$36 -> 0 | G24: =G23*Assumptions!$B$36 -> 0 | H24: =H23*Assumptions!$B$36 -> 0 | I24: =I23*Assumptions!$B$36 -> 0 | J24: =J23*Assumptions!$B$36 -> 0 | K24: =K23*Assumptions!$B$36 -> 0 | ... AQ24: =AQ23*Assumptions!$B$36 -> 0
A25: Cash Tax — Levered | D25: =IF(D9=1,0,D24) -> 0 | E25: =IF(E9=1,0,E24) -> 0 | F25: =IF(F9=1,0,F24) -> 0 | G25: =IF(G9=1,0,G24) -> 0 | H25: =IF(H9=1,0,H24) -> 0 | I25: =IF(I9=1,0,I24) -> 0 | J25: =IF(J9=1,0,J24) -> 0 | K25: =IF(K9=1,0,K24) -> 0 | ... AQ25: =IF(AQ9=1,0,AQ24) -> 0
A27: MEMO: UNLEVERED TAX CALCULATION (Project IRR only — assumes no debt financing)
A28: Taxable Income before TLCF (Unlevered) | D28: =D16-D12-D11 -> 0 | E28: =E16-E12-E11 -> 0 | F28: =F16-F12-F11 -> 0 | G28: =G16-G12-G11 -> -5.7379311 | H28: =H16-H12-H11 -> -5.3576897 | I28: =I16-I12-I11 -> -4.9698435 | J28: =J16-J12-J11 -> -4.5742404 | K28: =K16-K12-K11 -> -4.1707252 | ... AQ28: =AQ16-AQ12-AQ11 -> 0
A29: Opening TLCF (Unlevered) | D29: 0 | E29: =D32 -> 0 | F29: =E32 -> 0 | G29: =F32 -> 0 | H29: =G32 -> 5.7379311 | I29: =H32 -> 11.095621 | J29: =I32 -> 16.065464 | K29: =J32 -> 20.639705 | L29: =K32 -> 24.81043 | ... AQ29: =AP32 -> 0
A30: Loss Generated (Unlevered) | D30: =IF(D28<0,-D28,0) -> 0 | E30: =IF(E28<0,-E28,0) -> 0 | F30: =IF(F28<0,-F28,0) -> 0 | G30: =IF(G28<0,-G28,0) -> 5.7379311 | H30: =IF(H28<0,-H28,0) -> 5.3576897 | I30: =IF(I28<0,-I28,0) -> 4.9698435 | J30: =IF(J28<0,-J28,0) -> 4.5742404 | K30: =IF(K28<0,-K28,0) -> 4.1707252 | ... AQ30: =IF(AQ28<0,-AQ28,0) -> 0
A31: Loss Utilized (Unlevered) | D31: =MIN(D29,MAX(D28,0)) -> 0 | E31: =MIN(E29,MAX(E28,0)) -> 0 | F31: =MIN(F29,MAX(F28,0)) -> 0 | G31: =MIN(G29,MAX(G28,0)) -> 0 | H31: =MIN(H29,MAX(H28,0)) -> 0 | I31: =MIN(I29,MAX(I28,0)) -> 0 | J31: =MIN(J29,MAX(J28,0)) -> 0 | K31: =MIN(K29,MAX(K28,0)) -> 0 | ... AQ31: =MIN(AQ29,MAX(AQ28,0)) -> 0
A32: Closing TLCF (Unlevered) | D32: =D29+D30-D31 -> 0 | E32: =E29+E30-E31 -> 0 | F32: =F29+F30-F31 -> 0 | G32: =G29+G30-G31 -> 5.7379311 | H32: =H29+H30-H31 -> 11.095621 | I32: =I29+I30-I31 -> 16.065464 | J32: =J29+J30-J31 -> 20.639705 | K32: =K29+K30-K31 -> 24.81043 | ... AQ32: =AQ29+AQ30-AQ31 -> 0
A33: Taxable Income after TLCF (Unlevered) | D33: =MAX(D28,0)-D31 -> 0 | E33: =MAX(E28,0)-E31 -> 0 | F33: =MAX(F28,0)-F31 -> 0 | G33: =MAX(G28,0)-G31 -> 0 | H33: =MAX(H28,0)-H31 -> 0 | I33: =MAX(I28,0)-I31 -> 0 | J33: =MAX(J28,0)-J31 -> 0 | K33: =MAX(K28,0)-K31 -> 0 | ... AQ33: =MAX(AQ28,0)-AQ31 -> 0
A34: Tax Payable before Holiday (Unlevered) | D34: =D33*Assumptions!$B$36 -> 0 | E34: =E33*Assumptions!$B$36 -> 0 | F34: =F33*Assumptions!$B$36 -> 0 | G34: =G33*Assumptions!$B$36 -> 0 | H34: =H33*Assumptions!$B$36 -> 0 | I34: =I33*Assumptions!$B$36 -> 0 | J34: =J33*Assumptions!$B$36 -> 0 | K34: =K33*Assumptions!$B$36 -> 0 | ... AQ34: =AQ33*Assumptions!$B$36 -> 0
A35: Cash Tax — Unlevered | D35: =IF(D9=1,0,D34) -> 0 | E35: =IF(E9=1,0,E34) -> 0 | F35: =IF(F9=1,0,F34) -> 0 | G35: =IF(G9=1,0,G34) -> 0 | H35: =IF(H9=1,0,H34) -> 0 | I35: =IF(I9=1,0,I34) -> 0 | J35: =IF(J9=1,0,J34) -> 0 | K35: =IF(K9=1,0,K34) -> 0 | ... AQ35: =IF(AQ9=1,0,AQ34) -> 0

Sheet Project_CF
A1: PROJECT CASH FLOW — EBITDA TO CFADS BRIDGE
A2: CFADS = EBITDA less Cash Tax (levered) less Maintenance CAPEX. This is what debt sizing (Debt tab) is sculpted against.
A4: Calendar Year | D4: =Assumptions!D66 -> 2027 | E4: =Assumptions!E66 -> 2028 | F4: =Assumptions!F66 -> 2029 | G4: =Assumptions!G66 -> 2030 | H4: =Assumptions!H66 -> 2031 | I4: =Assumptions!I66 -> 2032 | J4: =Assumptions!J66 -> 2033 | K4: =Assumptions!K66 -> 2034 | ... AQ4: =Assumptions!AQ66 -> 2066
A5: Period | D5: =Assumptions!D67 -> Construction | E5: =Assumptions!E67 -> Construction | F5: =Assumptions!F67 -> Construction | G5: =Assumptions!G67 -> Operation | H5: =Assumptions!H67 -> Operation | I5: =Assumptions!I67 -> Operation | J5: =Assumptions!J67 -> Operation | K5: =Assumptions!K67 -> Operation | ... AQ5: =Assumptions!AQ67 -> -
A6: Operating Year # | D6: =Assumptions!D69 | E6: =Assumptions!E69 | F6: =Assumptions!F69 | G6: =Assumptions!G69 -> 1 | H6: =Assumptions!H69 -> 2 | I6: =Assumptions!I69 -> 3 | J6: =Assumptions!J69 -> 4 | K6: =Assumptions!K69 -> 5 | ... AQ6: =Assumptions!AQ69
A8: CONSTRUCTION PERIOD (US$ million)
A9: CAPEX Outflow (incl. VAT, Duty, Dev Costs; excl. financing fee) | D9: =CAPEX_SU!D10+CAPEX_SU!D11+CAPEX_SU!D12+CAPEX_SU!D13 -> 92.890025 | E9: =CAPEX_SU!E10+CAPEX_SU!E11+CAPEX_SU!E12+CAPEX_SU!E13 -> 127.33504 | F9: =CAPEX_SU!F10+CAPEX_SU!F11+CAPEX_SU!F12+CAPEX_SU!F13 -> 70.741687 | G9: =CAPEX_SU!G10+CAPEX_SU!G11+CAPEX_SU!G12+CAPEX_SU!G13 -> 0 | H9: =CAPEX_SU!H10+CAPEX_SU!H11+CAPEX_SU!H12+CAPEX_SU!H13 -> 0 | I9: =CAPEX_SU!I10+CAPEX_SU!I11+CAPEX_SU!I12+CAPEX_SU!I13 -> 0 | J9: =CAPEX_SU!J10+CAPEX_SU!J11+CAPEX_SU!J12+CAPEX_SU!J13 -> 0 | K9: =CAPEX_SU!K10+CAPEX_SU!K11+CAPEX_SU!K12+CAPEX_SU!K13 -> 0 | ... AQ9: =CAPEX_SU!AQ10+CAPEX_SU!AQ11+CAPEX_SU!AQ12+CAPEX_SU!AQ13 -> 0
A11: OPERATING PERIOD — LEVERED PROJECT CASH FLOW (drives CFADS)
A12: Revenue | D12: =Revenue_OPEX!D12 -> 0 | E12: =Revenue_OPEX!E12 -> 0 | F12: =Revenue_OPEX!F12 -> 0 | G12: =Revenue_OPEX!G12 -> 26.0172 | H12: =Revenue_OPEX!H12 -> 26.537544 | I12: =Revenue_OPEX!I12 -> 27.068295 | J12: =Revenue_OPEX!J12 -> 27.609661 | K12: =Revenue_OPEX!K12 -> 28.161854 | ... AQ12: =Revenue_OPEX!AQ12 -> 0
A13: Total Cash OPEX | D13: =Revenue_OPEX!D17 -> 0 | E13: =Revenue_OPEX!E17 -> 0 | F13: =Revenue_OPEX!F17 -> 0 | G13: =Revenue_OPEX!G17 -> 7.0051311 | H13: =Revenue_OPEX!H17 -> 7.1452337 | I13: =Revenue_OPEX!I17 -> 7.2881384 | J13: =Revenue_OPEX!J17 -> 7.4339012 | K13: =Revenue_OPEX!K17 -> 7.5825792 | ... AQ13: =Revenue_OPEX!AQ17 -> 0
A14: EBITDA | D14: =Revenue_OPEX!D19 -> 0 | E14: =Revenue_OPEX!E19 -> 0 | F14: =Revenue_OPEX!F19 -> 0 | G14: =Revenue_OPEX!G19 -> 19.012069 | H14: =Revenue_OPEX!H19 -> 19.39231 | I14: =Revenue_OPEX!I19 -> 19.780156 | J14: =Revenue_OPEX!J19 -> 20.17576 | K14: =Revenue_OPEX!K19 -> 20.579275 | ... AQ14: =Revenue_OPEX!AQ19 -> 0
A15: Accounting Depreciation | D15: =Tax!D13 -> 0 | E15: =Tax!E13 -> 0 | F15: =Tax!F13 -> 0 | G15: =Tax!G13 -> 8.25 | H15: =Tax!H13 -> 8.25 | I15: =Tax!I13 -> 8.25 | J15: =Tax!J13 -> 8.25 | K15: =Tax!K13 -> 8.25 | ... AQ15: =Tax!AQ13 -> 0
A16: EBIT (memo) | D16: =D14-D15 -> 0 | E16: =E14-E15 -> 0 | F16: =F14-F15 -> 0 | G16: =G14-G15 -> 10.762069 | H16: =H14-H15 -> 11.14231 | I16: =I14-I15 -> 11.530156 | J16: =J14-J15 -> 11.92576 | K16: =K14-K15 -> 12.329275 | ... AQ16: =AQ14-AQ15 -> 0
A17: Interest Expense | D17: =Debt!D23 -> 0 | E17: =Debt!E23 -> 0 | F17: =Debt!F23 -> 0 | G17: =Debt!G23 -> 9.8631599 | H17: =Debt!H23 -> 9.5731748 | I17: =Debt!I23 -> 9.2457188 | J17: =Debt!J23 -> 8.8779839 | K17: =Debt!K23 -> 8.4669721 | ... AQ17: =Debt!AQ23 -> 0
A18: Cash Tax — Levered | D18: =Tax!D25 -> 0 | E18: =Tax!E25 -> 0 | F18: =Tax!F25 -> 0 | G18: =Tax!G25 -> 0 | H18: =Tax!H25 -> 0 | I18: =Tax!I25 -> 0 | J18: =Tax!J25 -> 0 | K18: =Tax!K25 -> 0 | ... AQ18: =Tax!AQ25 -> 0
A19: Net Operating Cash Flow (memo) | D19: =D14-D18 -> 0 | E19: =E14-E18 -> 0 | F19: =F14-F18 -> 0 | G19: =G14-G18 -> 19.012069 | H19: =H14-H18 -> 19.39231 | I19: =I14-I18 -> 19.780156 | J19: =J14-J18 -> 20.17576 | K19: =K14-K18 -> 20.579275 | ... AQ19: =AQ14-AQ18 -> 0
A20: Maintenance CAPEX | D20: =D12*Assumptions!$B$55 -> 0 | E20: =E12*Assumptions!$B$55 -> 0 | F20: =F12*Assumptions!$B$55 -> 0 | G20: =G12*Assumptions!$B$55 -> 0.390258 | H20: =H12*Assumptions!$B$55 -> 0.39806316 | I20: =I12*Assumptions!$B$55 -> 0.40602442 | J20: =J12*Assumptions!$B$55 -> 0.41414491 | K20: =K12*Assumptions!$B$55 -> 0.42242781 | ... AQ20: =AQ12*Assumptions!$B$55 -> 0
A21: CFADS — Cash Flow Available for Debt Service | D21: =D14-D18-D20 -> 0 | E21: =E14-E18-E20 -> 0 | F21: =F14-F18-F20 -> 0 | G21: =G14-G18-G20 -> 18.621811 | H21: =H14-H18-H20 -> 18.994247 | I21: =I14-I18-I20 -> 19.374132 | J21: =J14-J18-J20 -> 19.761615 | K21: =K14-K18-K20 -> 20.156847 | ... AQ21: =AQ14-AQ18-AQ20 -> 0
A23: MEMO: UNLEVERED CASH FLOW (Project IRR — before financing)
A24: Cash Tax — Unlevered | D24: =Tax!D35 -> 0 | E24: =Tax!E35 -> 0 | F24: =Tax!F35 -> 0 | G24: =Tax!G35 -> 0 | H24: =Tax!H35 -> 0 | I24: =Tax!I35 -> 0 | J24: =Tax!J35 -> 0 | K24: =Tax!K35 -> 0 | ... AQ24: =Tax!AQ35 -> 0
A25: Unlevered Net Cash Flow | D25: =D14-D24-D20 -> 0 | E25: =E14-E24-E20 -> 0 | F25: =F14-F24-F20 -> 0 | G25: =G14-G24-G20 -> 18.621811 | H25: =H14-H24-H20 -> 18.994247 | I25: =I14-I24-I20 -> 19.374132 | J25: =J14-J24-J20 -> 19.761615 | K25: =K14-K24-K20 -> 20.156847 | ... AQ25: =AQ14-AQ24-AQ20 -> 0
A26: Project Pre-Financing Cash Flow | D26: =-D9+D25 -> -92.890025 | E26: =-E9+E25 -> -127.33504 | F26: =-F9+F25 -> -70.741687 | G26: =-G9+G25 -> 18.621811 | H26: =-H9+H25 -> 18.994247 | I26: =-I9+I25 -> 19.374132 | J26: =-J9+J25 -> 19.761615 | K26: =-K9+K25 -> 20.156847 | ... AQ26: =-AQ9+AQ25 -> 0

Sheet Debt
A1: DEBT SIZING & SCHEDULE — DSCR SCULPTING
A2: Required DSCR, Interest Rate and Debt Tenor are INPUTS. The Loan Amount is an OUTPUT: the PV, at the interest rate, of the sculpted debt service stream (CFADS / Required DSCR) over the debt tenor.
A4: Calendar Year | D4: =Assumptions!D66 -> 2027 | E4: =Assumptions!E66 -> 2028 | F4: =Assumptions!F66 -> 2029 | G4: =Assumptions!G66 -> 2030 | H4: =Assumptions!H66 -> 2031 | I4: =Assumptions!I66 -> 2032 | J4: =Assumptions!J66 -> 2033 | K4: =Assumptions!K66 -> 2034 | ... AQ4: =Assumptions!AQ66 -> 2066
A5: Period | D5: =Assumptions!D67 -> Construction | E5: =Assumptions!E67 -> Construction | F5: =Assumptions!F67 -> Construction | G5: =Assumptions!G67 -> Operation | H5: =Assumptions!H67 -> Operation | I5: =Assumptions!I67 -> Operation | J5: =Assumptions!J67 -> Operation | K5: =Assumptions!K67 -> Operation | ... AQ5: =Assumptions!AQ67 -> -
A6: Operating Year # | D6: =Assumptions!D69 | E6: =Assumptions!E69 | F6: =Assumptions!F69 | G6: =Assumptions!G69 -> 1 | H6: =Assumptions!H69 -> 2 | I6: =Assumptions!I69 -> 3 | J6: =Assumptions!J69 -> 4 | K6: =Assumptions!K69 -> 5 | ... AQ6: =Assumptions!AQ69
A7: Debt Year # | D7: =Assumptions!D70 | E7: =Assumptions!E70 | F7: =Assumptions!F70 | G7: =Assumptions!G70 -> 1 | H7: =Assumptions!H70 -> 2 | I7: =Assumptions!I70 -> 3 | J7: =Assumptions!J70 -> 4 | K7: =Assumptions!K70 -> 5 | ... AQ7: =Assumptions!AQ70
A9: DEBT SIZING (CFADS ÷ Required DSCR ÷ Interest Rate ÷ Tenor → Maximum Loan Amount)
A10: CFADS | D10: =Project_CF!D21 -> 0 | E10: =Project_CF!E21 -> 0 | F10: =Project_CF!F21 -> 0 | G10: =Project_CF!G21 -> 18.621811 | H10: =Project_CF!H21 -> 18.994247 | I10: =Project_CF!I21 -> 19.374132 | J10: =Project_CF!J21 -> 19.761615 | K10: =Project_CF!K21 -> 20.156847 | ... AQ10: =Project_CF!AQ21 -> 0
A11: Within Debt Tenor (1/0) | D11: =IF(D7<>"",1,0) -> 0 | E11: =IF(E7<>"",1,0) -> 0 | F11: =IF(F7<>"",1,0) -> 0 | G11: =IF(G7<>"",1,0) -> 1 | H11: =IF(H7<>"",1,0) -> 1 | I11: =IF(I7<>"",1,0) -> 1 | J11: =IF(J7<>"",1,0) -> 1 | K11: =IF(K7<>"",1,0) -> 1 | ... AQ11: =IF(AQ7<>"",1,0) -> 0
A12: Max Debt Service (Target) = CFADS ÷ Required DSCR | D12: =IF(D11=1,D10/$C$16,0) -> 0 | E12: =IF(E11=1,E10/$C$16,0) -> 0 | F12: =IF(F11=1,F10/$C$16,0) -> 0 | G12: =IF(G11=1,G10/$C$16,0) -> 14.32447 | H12: =IF(H11=1,H10/$C$16,0) -> 14.610959 | I12: =IF(I11=1,I10/$C$16,0) -> 14.903179 | J12: =IF(J11=1,J10/$C$16,0) -> 15.201242 | K12: =IF(K11=1,K10/$C$16,0) -> 15.505267 | ... AQ12: =IF(AQ11=1,AQ10/$C$16,0) -> 0
A13: Discount Factor @ Interest Rate | D13: =IF(D11=1,1/(1+$C$17)^D7,0) -> 0 | E13: =IF(E11=1,1/(1+$C$17)^E7,0) -> 0 | F13: =IF(F11=1,1/(1+$C$17)^F7,0) -> 0 | G13: =IF(G11=1,1/(1+$C$17)^G7,0) -> 0.93896714 | H13: =IF(H11=1,1/(1+$C$17)^H7,0) -> 0.88165928 | I13: =IF(I11=1,1/(1+$C$17)^I7,0) -> 0.82784909 | J13: =IF(J11=1,1/(1+$C$17)^J7,0) -> 0.77732309 | K13: =IF(K11=1,1/(1+$C$17)^K7,0) -> 0.72988084 | ... AQ13: =IF(AQ11=1,1/(1+$C$17)^AQ7,0) -> 0
A14: PV of Max Debt Service | D14: =D12*D13 -> 0 | E14: =E12*E13 -> 0 | F14: =F12*F13 -> 0 | G14: =G12*G13 -> 13.450207 | H14: =H12*H13 -> 12.881888 | I14: =I12*I13 -> 12.337583 | J14: =J12*J13 -> 11.816276 | K14: =K12*K13 -> 11.316997 | ... AQ14: =AQ12*AQ13 -> 0
A16: Required DSCR (x) | C16: =Assumptions!$B$58 -> 1.3
A17: Interest Rate (%) | C17: =Assumptions!$B$59 -> 0.065
A18: Debt Tenor (years) | C18: =Assumptions!$B$60 -> 15
A19: Maximum Loan Amount (US$m) | C19: =SUM(D14:AQ14) -> 151.74092
A21: DEBT SCHEDULE
A22: Opening Balance | D22: =IF(D11=1,IF(D7=1,$C$19,0),0) -> 0 | E22: =IF(E11=1,IF(E7=1,$C$19,D26),0) -> 0 | F22: =IF(F11=1,IF(F7=1,$C$19,E26),0) -> 0 | G22: =IF(G11=1,IF(G7=1,$C$19,F26),0) -> 151.74092 | H22: =IF(H11=1,IF(H7=1,$C$19,G26),0) -> 147.27961 | I22: =IF(I11=1,IF(I7=1,$C$19,H26),0) -> 142.24183 | J22: =IF(J11=1,IF(J7=1,$C$19,I26),0) -> 136.58437 | K22: =IF(K11=1,IF(K7=1,$C$19,J26),0) -> 130.26111 | L22: =IF(L11=1,IF(L7=1,$C$19,K26),0) -> 123.22281 | ... AQ22: =IF(AQ11=1,IF(AQ7=1,$C$19,AP26),0) -> 0
A23: Interest Expense | D23: =D22*$C$17 -> 0 | E23: =E22*$C$17 -> 0 | F23: =F22*$C$17 -> 0 | G23: =G22*$C$17 -> 9.8631599 | H23: =H22*$C$17 -> 9.5731748 | I23: =I22*$C$17 -> 9.2457188 | J23: =J22*$C$17 -> 8.8779839 | K23: =K22*$C$17 -> 8.4669721 | ... AQ23: =AQ22*$C$17 -> 0
A24: Principal Repayment | D24: =IF(D11=1,MIN(MAX(D12-D23,0),D22),0) -> 0 | E24: =IF(E11=1,MIN(MAX(E12-E23,0),E22),0) -> 0 | F24: =IF(F11=1,MIN(MAX(F12-F23,0),F22),0) -> 0 | G24: =IF(G11=1,MIN(MAX(G12-G23,0),G22),0) -> 4.46131 | H24: =IF(H11=1,MIN(MAX(H12-H23,0),H22),0) -> 5.0377846 | I24: =IF(I11=1,MIN(MAX(I12-I23,0),I22),0) -> 5.6574597 | J24: =IF(J11=1,MIN(MAX(J12-J23,0),J22),0) -> 6.3232582 | K24: =IF(K11=1,MIN(MAX(K12-K23,0),K22),0) -> 7.0382948 | ... AQ24: =IF(AQ11=1,MIN(MAX(AQ12-AQ23,0),AQ22),0) -> 0
A25: Actual Debt Service | D25: =D23+D24 -> 0 | E25: =E23+E24 -> 0 | F25: =F23+F24 -> 0 | G25: =G23+G24 -> 14.32447 | H25: =H23+H24 -> 14.610959 | I25: =I23+I24 -> 14.903179 | J25: =J23+J24 -> 15.201242 | K25: =K23+K24 -> 15.505267 | ... AQ25: =AQ23+AQ24 -> 0
A26: Closing Balance | D26: =D22-D24 -> 0 | E26: =E22-E24 -> 0 | F26: =F22-F24 -> 0 | G26: =G22-G24 -> 147.27961 | H26: =H22-H24 -> 142.24183 | I26: =I22-I24 -> 136.58437 | J26: =J22-J24 -> 130.26111 | K26: =K22-K24 -> 123.22281 | ... AQ26: =AQ22-AQ24 -> 0
A27: Actual DSCR | D27: =IF(D25>0,D10/D25,"") | E27: =IF(E25>0,E10/E25,"") | F27: =IF(F25>0,F10/F25,"") | G27: =IF(G25>0,G10/G25,"") -> 1.3 | H27: =IF(H25>0,H10/H25,"") -> 1.3 | I27: =IF(I25>0,I10/I25,"") -> 1.3 | J27: =IF(J25>0,J10/J25,"") -> 1.3 | K27: =IF(K25>0,K10/K25,"") -> 1.3 | ... AQ27: =IF(AQ25>0,AQ10/AQ25,"")
A29: CHECKS
A30: Ending Debt Balance (should be ~0 at final debt year) | C30: =INDEX(D26:AQ26,MATCH($C$18,D7:AQ7,0)) -> 0
A31: Minimum Actual DSCR | C31: =MIN(D27:AQ27) -> 1.3
A32: Average Actual DSCR | C32: =AVERAGE(D27:AQ27) -> 1.3

Sheet Equity
A1: EQUITY CASH FLOW & RETURNS
A2: Equity funds construction as the residual after debt (Sources & Uses); operating distributions are CFADS remaining after actual debt service.
A4: Calendar Year | D4: =Assumptions!D66 -> 2027 | E4: =Assumptions!E66 -> 2028 | F4: =Assumptions!F66 -> 2029 | G4: =Assumptions!G66 -> 2030 | H4: =Assumptions!H66 -> 2031 | I4: =Assumptions!I66 -> 2032 | J4: =Assumptions!J66 -> 2033 | K4: =Assumptions!K66 -> 2034 | ... AQ4: =Assumptions!AQ66 -> 2066
A5: Period | D5: =Assumptions!D67 -> Construction | E5: =Assumptions!E67 -> Construction | F5: =Assumptions!F67 -> Construction | G5: =Assumptions!G67 -> Operation | H5: =Assumptions!H67 -> Operation | I5: =Assumptions!I67 -> Operation | J5: =Assumptions!J67 -> Operation | K5: =Assumptions!K67 -> Operation | ... AQ5: =Assumptions!AQ67 -> -
A6: Operating Year # | D6: =Assumptions!D69 | E6: =Assumptions!E69 | F6: =Assumptions!F69 | G6: =Assumptions!G69 -> 1 | H6: =Assumptions!H69 -> 2 | I6: =Assumptions!I69 -> 3 | J6: =Assumptions!J69 -> 4 | K6: =Assumptions!K69 -> 5 | ... AQ6: =Assumptions!AQ69
A8: EQUITY CASH FLOW (US$ million)
A9: Equity Contribution (Construction) | D9: =CAPEX_SU!D19 -> 44.823321 | E9: =CAPEX_SU!E19 -> 61.444479 | F9: =CAPEX_SU!F19 -> 35.234142 | G9: =CAPEX_SU!G19 -> 0 | H9: =CAPEX_SU!H19 -> 0 | I9: =CAPEX_SU!I19 -> 0 | J9: =CAPEX_SU!J19 -> 0 | K9: =CAPEX_SU!K19 -> 0 | ... AQ9: =CAPEX_SU!AQ19 -> 0
A10: CFADS (memo) | D10: =Project_CF!D21 -> 0 | E10: =Project_CF!E21 -> 0 | F10: =Project_CF!F21 -> 0 | G10: =Project_CF!G21 -> 18.621811 | H10: =Project_CF!H21 -> 18.994247 | I10: =Project_CF!I21 -> 19.374132 | J10: =Project_CF!J21 -> 19.761615 | K10: =Project_CF!K21 -> 20.156847 | ... AQ10: =Project_CF!AQ21 -> 0
A11: Debt Service — Actual (memo) | D11: =Debt!D25 -> 0 | E11: =Debt!E25 -> 0 | F11: =Debt!F25 -> 0 | G11: =Debt!G25 -> 14.32447 | H11: =Debt!H25 -> 14.610959 | I11: =Debt!I25 -> 14.903179 | J11: =Debt!J25 -> 15.201242 | K11: =Debt!K25 -> 15.505267 | ... AQ11: =Debt!AQ25 -> 0
A12: Distribution to Equity | D12: =IF(D6<>"",D10-D11,0) -> 0 | E12: =IF(E6<>"",E10-E11,0) -> 0 | F12: =IF(F6<>"",F10-F11,0) -> 0 | G12: =IF(G6<>"",G10-G11,0) -> 4.297341 | H12: =IF(H6<>"",H10-H11,0) -> 4.3832878 | I12: =IF(I6<>"",I10-I11,0) -> 4.4709536 | J12: =IF(J6<>"",J10-J11,0) -> 4.5603726 | K12: =IF(K6<>"",K10-K11,0) -> 4.6515801 | ... AQ12: =IF(AQ6<>"",AQ10-AQ11,0) -> 0
A13: Equity Cash Flow | D13: =-D9+D12 -> -44.823321 | E13: =-E9+E12 -> -61.444479 | F13: =-F9+F12 -> -35.234142 | G13: =-G9+G12 -> 4.297341 | H13: =-H9+H12 -> 4.3832878 | I13: =-I9+I12 -> 4.4709536 | J13: =-J9+J12 -> 4.5603726 | K13: =-K9+K12 -> 4.6515801 | ... AQ13: =-AQ9+AQ12 -> 0
A14: Cumulative Equity Cash Flow | D14: =D13 -> -44.823321 | E14: =D14+E13 -> -106.2678 | F14: =E14+F13 -> -141.50194 | G14: =F14+G13 -> -137.2046 | H14: =G14+H13 -> -132.82131 | I14: =H14+I13 -> -128.35036 | J14: =I14+J13 -> -123.78999 | K14: =J14+K13 -> -119.13841 | L14: =K14+L13 -> -114.3938 | ... AQ14: =AP14+AQ13 -> 288.44803
A16: MEMO: PROJECT PRE-FINANCING CASH FLOW (for Project IRR)
A17: Project Pre-Financing Cash Flow | D17: =Project_CF!D26 -> -92.890025 | E17: =Project_CF!E26 -> -127.33504 | F17: =Project_CF!F26 -> -70.741687 | G17: =Project_CF!G26 -> 18.621811 | H17: =Project_CF!H26 -> 18.994247 | I17: =Project_CF!I26 -> 19.374132 | J17: =Project_CF!J26 -> 19.761615 | K17: =Project_CF!K26 -> 20.156847 | ... AQ17: =Project_CF!AQ26 -> 0
A19: RETURNS SUMMARY
A20: Equity IRR | C20: =IRR(D13:AQ13,0.12) -> 0.056970658
A21: Equity NPV (US$m) @ Cost of Equity | C21: =D13+NPV(Assumptions!$B$61,E13:AQ13) -> -87.772799
A22: Project IRR | C22: =IRR(D17:AQ17,0.1) -> 0.054760763
A23: Project NPV (US$m) @ WACC | C23: =D17+NPV(Assumptions!$B$62,E17:AQ17) -> -105.91397
A25: FINANCING SUMMARY (for reference)
A26: Maximum Debt Capacity (US$m) | C26: =Debt!$C$19 -> 151.74092
A27: Equity Requirement (US$m) | C27: =CAPEX_SU!$C$33 -> 141.50194
A28: Debt % of Funding | C28: =CAPEX_SU!$C$32 -> 0.51745819
A29: Minimum Actual DSCR | C29: =Debt!$C$31 -> 1.3
A30: Average Actual DSCR | C30: =Debt!$C$32 -> 1.3

Sheet Dashboard
A1: GEOTHERMAL POWER PROJECT — DASHBOARD
A2: Live summary of key assumptions and outputs. Change inputs on the Assumptions tab to run a new scenario.
A4: =Equity!C20 -> 0.056970658 | D4: =Equity!C22 -> 0.054760763 | F4: =Debt!C19 -> 151.74092 | H4: =CAPEX_SU!C33 -> 141.50194 | J4: =CAPEX_SU!C32 -> 0.51745819
A8: EQUITY IRR (key output) | D8: PROJECT IRR | F8: MAX. DEBT CAPACITY (US$m) | H8: EQUITY REQUIREMENT (US$m) | J8: DEBT % OF FUNDING
A11: PROJECT | E11: COMMERCIAL
A12: Installed Capacity (MW) | C12: =Assumptions!$B$13 -> 55 | E12: Starting Tariff (US$/kWh) | G12: =Assumptions!$B$46 -> 0.06
A13: Capacity Factor | C13: =Assumptions!$B$14 -> 0.9 | E13: Tariff Escalation (% p.a.) | G13: =Assumptions!$B$47 -> 0.02
A14: Annual Generation (GWh) | C14: =Assumptions!$B$15 -> 433.62 | E14: Tariff Structure | G14: =Assumptions!$B$48 -> Escalated
A15: COD | C15: =Assumptions!$B$7 -> 47484 | E15: PPA Tenor (years) | G15: =Assumptions!$B$9 -> 30
A16: Construction Period (years) | C16: =Assumptions!$B$6 -> 3 | E16: Year 1 Revenue (US$m) | G16: =Revenue_OPEX!G12 -> 26.0172
A17: Operating Life (years) | C17: =Assumptions!$B$8 -> 30 | E17: Year 1 EBITDA (US$m) | G17: =Revenue_OPEX!G19 -> 19.012069
A18: PPA Tenor (years) | C18: =Assumptions!$B$9 -> 30 | E18: Tax Incentive Scenario | G18: =Assumptions!$B$43 -> Holiday + Allowance
A20: CAPEX | E20: FINANCING
A21: Total CAPEX (US$m) | C21: =Assumptions!$B$19 -> 247.5 | E21: Required DSCR (x) | G21: =Assumptions!$B$58 -> 1.3
A22: VAT (US$m) | C22: =CAPEX_SU!C26 -> 28.04175 | E22: Interest Rate (%) | G22: =Assumptions!$B$59 -> 0.065
A23: Import Duty (US$m) | C23: =CAPEX_SU!C25 -> 7.425 | E23: Debt Tenor (years) | G23: =Assumptions!$B$60 -> 15
A24: Development Costs (US$m) | C24: =CAPEX_SU!C27 -> 8 | E24: Maximum Debt Capacity (US$m) | G24: =Debt!C19 -> 151.74092
A25: Financing Fee (US$m) | C25: =CAPEX_SU!C28 -> 2.2761138 | E25: Debt / Total Funding (%) | G25: =CAPEX_SU!C32 -> 0.51745819
A26: Total Project Cost (US$m) | C26: =CAPEX_SU!C29 -> 293.24286 | E26: Equity Requirement (US$m) | G26: =CAPEX_SU!C33 -> 141.50194
E27: Min / Avg Actual DSCR | G27: =Debt!C31 -> 1.3
A29: RETURNS (key outputs)
A30: Project IRR | C30: =Equity!C22 -> 0.054760763 | E30: Equity IRR | G30: =Equity!C20 -> 0.056970658
A31: Project NPV (US$m) | C31: =Equity!C23 -> -105.91397 | E31: Equity NPV (US$m) | G31: =Equity!C21 -> -87.772799
A33: HOW THIS MODEL WORKS
A34: • Model flow: Assumptions -> Revenue/OPEX -> EBITDA -> Tax -> Project Cash Flow / CFADS -> Debt Sizing -> Debt Schedule -> Equity Cash Flow -> Equity IRR.
A35: • All inputs live on the Assumptions tab (blue). The Loan Amount (Debt tab) is an OUTPUT: CFADS / Required DSCR, sized as the PV of that sculpted debt service at the interest rate over the debt tenor.
A36: • Equity Requirement = Total Project Cost - Maximum Debt Capacity (CAPEX_SU tab). Equity IRR is computed from actual equity contributions and distributions (Equity tab).
A37: • Tax Incentive Scenario (Assumptions!B43) switches between None / Tax Holiday Only / Tax Allowance Only / Holiday + Allowance so incentive combinations can be compared directly.
A38: • The CFADS <-> interest <-> debt sizing loop is circular by construction (standard for DSCR-sculpted project finance debt); this workbook has iterative calculation enabled — if Excel prompts about circular references, enable iterative calculation in File > Options > Formulas.
A39: • See the Sensitivity tab for pre-computed Equity IRR / Debt Capacity grids across CAPEX, tariff, interest rate, DSCR, tenor and tax incentives.
